- [异常简述](#异常简述)
  - [处理异常](#处理异常)
  - [异常输出](#异常输出)
      - [sys.exc\_info()方法：获取异常信息](#sysexc_info方法获取异常信息)
      - [traceback进行获取](#traceback进行获取)
- [自定义异常](#自定义异常)
  - [基础异常](#基础异常)
  - [自定义](#自定义)


# 异常简述

异常，通常是指程序运行的过程中遇到了错误，终止并退出。我们通常使用try except语句去处理异常，这样程序就不会被终止，仍能继续执行。

处理异常时，如果有必须执行的语句，比如文件打开后必须关闭等等，则可以放在finally block中。

## 处理异常

- 不要乱用异常， 到底用try 还是 if 要根据实际情况选择
- try--except (traceback.format_exc()) 这种会执行except后继续往下执行
- try--except （raise） 会在except时raise抛出，不往下执行了
- if a: raise 则是直接抛出，不往下执行

```python
try:
    statement(s)            # 要检测的语句块
except exception1：
    deal_exception_code # 如果在 try 部份引发了 'exception' 异常
except (Exception1[, Exception2[,...ExceptionN]]]) :
    deal_all_other_exception2_code # 处理多个异常
except:
    deal_all_other_exception2_code # 处理全部其它异常
    print('a')
    raise 
else:
    no_exception_happend_code #如果没有异常发生

try:
    # <语句>
finally:
    # <语句>    #退出try时总会执行

>>> raise
Traceback (most recent call last):
  File "<pyshell#1>", line 1, in <module>
    raise
RuntimeError: No active exception to reraise
>>> raise ZeroDivisionError
Traceback (most recent call last):
  File "<pyshell#0>", line 1, in <module>
    raise ZeroDivisionError
ZeroDivisionError
>>> raise ZeroDivisionError("除数不能为零")
Traceback (most recent call last):
  File "<pyshell#2>", line 1, in <module>
    raise ZeroDivisionError("除数不能为零")
ZeroDivisionError: 除数不能为零
```

## 异常输出

#### sys.exc_info()方法：获取异常信息

exc_info() 方法会将当前的异常信息以元组的形式返回，该元组中包含 3 个元素，分别为 type、value 和 traceback，它们的含义分别是：

- type：异常类型的名称，它是 BaseException 的子类
- value：捕获到的异常实例。
- traceback：是一个 traceback 对象。

```Python
from pprint import pprint
import sys


try:
    print("30除以",0,"等于",30/0)
except Exception as e:
    pprint(e.__dict__)
    # pprint(dir(e)) # dir(obj) 将返回实例的所有属性和方法，包括从类继承的属性和方法
    pprint(sys.exc_info())
    raise e


{}
(<class 'ZeroDivisionError'>,
 ZeroDivisionError('division by zero'),
 <traceback object at 0xffffb2364fc0>)

# sys.exc_info() 
<class 'ZeroDivisionError'>,
 ZeroDivisionError('division by zero'),
 <traceback object at 0xffffb2364fc0>)

Traceback (most recent call last):
  File "/home/wanglongxin/youling/fuxi-sdk-python3/result/exce.py", line 11, in <module>
    raise e
  File "/home/wanglongxin/youling/fuxi-sdk-python3/result/exce.py", line 6, in <module>
    print("30除以",0,"等于",30/0)
ZeroDivisionError: division by zero

```

#### traceback进行获取

- traceback.print_exc() 直接打印异常 **(类似于没有通过try捕获异常，解析器直接报错的状态。) 
- traceback.format_exc() 返回字符串  (将异常的详细信息以字符串的形式返回)
- traceback.print_exc(file=open(‘你要保存的文件名.txt’,’a+’))    （直接将详细的异常信息保存在文件中）

```Python
import sys
import traceback
class SelfException(Exception): pass

def main():
    try:
        print("30除以",0,"等于",30/0)
    except Exception as e:
        # print(e.__dict__)
        # pprint(dir(e)) # dir(obj) 将返回实例的所有属性和方法，包括从类继承的属性和方法
        # print(sys.exc_info())
        raise e

try:
    main()
except:
    # 捕捉异常，并将异常传播信息输出控制台
    traceback.print_exc()
    print(traceback.format_exc()) # 用的比较多
    # 捕捉异常，并将异常传播信息输出指定文件中
    # traceback.print_exc(file=open('log.txt', 'a'))

Traceback (most recent call last):
  File "/home/wanglongxin/youling/fuxi-sdk-python3/result/exce.py", line 15, in <module>
    main()
  File "/home/wanglongxin/youling/fuxi-sdk-python3/result/exce.py", line 12, in main
    raise e
  File "/home/wanglongxin/youling/fuxi-sdk-python3/result/exce.py", line 7, in main
    print("30除以",0,"等于",30/0)
ZeroDivisionError: division by zero

Traceback (most recent call last):
  File "/home/wanglongxin/youling/fuxi-sdk-python3/result/exce.py", line 15, in <module>
    main()
  File "/home/wanglongxin/youling/fuxi-sdk-python3/result/exce.py", line 12, in main
    raise e
  File "/home/wanglongxin/youling/fuxi-sdk-python3/result/exce.py", line 7, in main
    print("30除以",0,"等于",30/0)
ZeroDivisionError: division by zero
```

# 自定义异常

## 基础异常 

首先， 自定义异常类应该总是继承自内置的 Exception 类，或者是继承自那些本身就是从 Exception 继承而来的类。

```python
class Exception(BaseException)
 |  Common base class for all non-exit exceptions.
 |
 |  Method resolution order:
 |      Exception
 |      BaseException
 |      object
 |
 |  Built-in subclasses:
 |      ArithmeticError
 |      AssertionError
 |      AttributeError
 |      BufferError
 |      ... and 15 other subclasses
 |
 |  Methods defined here:
 |
 |  __init__(self, /, *args, **kwargs)
 |      Initialize self.  See help(type(self)) for accurate signature.
 |
 |  ----------------------------------------------------------------------
 |  Static methods defined here:
 |
 |  __new__(*args, **kwargs) from builtins.type
 |      Create and return a new object.  See help(type) for accurate signature.
 |
 |  ----------------------------------------------------------------------
 |  Methods inherited from BaseException:
 |
 |  __delattr__(self, name, /)
 |      Implement delattr(self, name).
 |
 |  __getattribute__(self, name, /)
 |      Return getattr(self, name).
 |
 |  __reduce__(...)
 |      Helper for pickle.
 |
 |  __repr__(self, /)
 |      Return repr(self).
 |
 |  __setattr__(self, name, value, /)
 |      Implement setattr(self, name, value).
 |
 |  __setstate__(...)
 |
 |  __str__(self, /)
 |      Return str(self).
 |
 |  with_traceback(...)
 |      Exception.with_traceback(tb) --
 |      set self.__traceback__ to tb and return self.
 |
 |  ----------------------------------------------------------------------
 |  Data descriptors inherited from BaseException:
 |
 |  __cause__
 |      exception cause
 |
 |  __context__
 |      exception context
 |
 |  __dict__
 |
 |  __suppress_context__
 |
 |  __traceback__
 |
 |  args
```

Exception 的参数包含： *args, **kwargs. 测试过程， 很明显， Exception 可以接受任意数量的 位置参数, 而 关键字 参数不会被使用。


```python
>>> raise Exception('exception')
Traceback (most recent call last):
  File "<stdin>", line 1, in <module>
Exception: exception

>>> raise Exception('exception', 2)
Traceback (most recent call last):
  File "<stdin>", line 1, in <module>
Exception: ('exception', 2)

>>> raise Exception('exception', 2, name='Test')
Traceback (most recent call last):
  File "<stdin>", line 1, in <module>
TypeError: exceptions.Exception does not take keyword arguments

>>> try:
...     raise Exception(1, 2, 3)
... except Exception as ex:
...     print(ex.args)
...
(1, 2, 3)
```

## 自定义

```python
import traceback


class MyException(Exception):
    """自定义异常。"""
    def __init__(self, message, status, more=None):
        super().__init__(message)
        self.message = message
        self.status = status
        self.more = more

# 现在您可以使用特定的细节触发此异常
try:
    # 触发异常的某些条件
    raise MyException("出了些问题", 500, "额外信息")
except MyException as e:
    print(f"错误：{e.message}，状态：{e.status}，更多信息：{e.more}")
    print(traceback.format_exc())


错误：出了些问题，状态：500，更多信息：额外信息

Traceback (most recent call last):
  File "/Users/wanglongxin/Desktop/yaotai/conference-service/tests/test_wlx.py", line 15, in <module>
    raise MyException("出了些问题", 500, "额外信息")
MyException: 出了些问题
```

```python
# 自定义异常类，只需要创建一个类继承Exception即可
# 自定义异常类完全不用写任何内容
class MyError(Exception):
    pass

def add(a, b):
    # 如果a和b中有负数，就向调用处抛出异常
    if a < 0 or b < 0:
        # raise用于向外部抛出异常，后边可以跟一个异常类，或异常类的实例
        # 此时返回一个异常类的实例
        raise MyError("传入的参数不能有负数。自定义的，这样也行！")
    # 正常计算并返回结果
    r = a + b
    return r


print(add(-123, 456))

Traceback (most recent call last):
  File "/Users/wanglongxin/Desktop/yaotai/conference-service/tests/test_wlx.py", line 17, in <module>
    print(add(-123, 456))
  File "/Users/wanglongxin/Desktop/yaotai/conference-service/tests/test_wlx.py", line 11, in add
    raise MyError("传入的参数不能有负数。自定义的，这样也行！")
__main__.MyError: 传入的参数不能有负数。自定义的，这样也行！
```

```python
import logging
import os
import sys
import time
#创建一个日志记录器
logger=logging.getLogger(__name__)
logger.setLevel(logging.DEBUG) #设置日志记录器的最低输出级别为DEBUG
 
#设置日志格式
formatter = logging.Formatter("%(asctime)s - %(name)s - %(levelname)s - %(message)s", datefmt="%Y-%m-%d %H:%M:%S")

 
#添加日志处理器，控制台、文件
#控制台日志
stream_handler=logging.StreamHandler() #输出到控制台
stream_handler.setFormatter(formatter) #设置日志格式
stream_handler.setLevel(logging.INFO) #单独设置控制台的输出级别为INFO
 
#文件日志
log_file_path = os.path.join("logs/", f"{time.strftime('%Y-%m-%d')}_app.log")
file_handler = logging.FileHandler(filename=log_file_path, encoding='utf-8', mode='w')
file_handler.setFormatter(formatter)#设置日志格式
file_handler.setLevel(logging.DEBUG)#单独设置文件日志的输出级别为DEBUG
 
#添加日志处理器
logger.addHandler(file_handler)
logger.addHandler(stream_handler)

# 检查文件的读权限
def check_read_permission(file_path):
    return os.access(file_path, os.R_OK)

# 检查文件的写权限
def check_write_permission(file_path):
    return os.access(file_path, os.W_OK)

print(check_write_permission(r"log_dir/2024-06-28_app.log"))



class MyException(Exception):
    """自定义异常
    
    help(Exception) 本身init就可接受位置参数，不可接受关键字参数，所以我们需要在init中传入位置参数。
    """
    def __init__(self, message, status, more=None):
        super().__init__(message)
        self.message = message
        self.status = status
        self.more = more
    
    # 重写__str__方法，打印出自定义的错误信息 默认str方法会打印出异常的信息meassage
    def __str__(self):
        return f"错误：{self.args[0]}，状态：{self.status}，更多信息：{self.more}"


# 现在您可以使用特定的细节触发此异常
try:
    # 触发异常的某些条件
    raise MyException("出了些问题", 500, "额外信息")
except MyException as e:
    logger.error(f"错误：{e.message}，状态：{e.status}，更多信息：{e.more}")
    logger.info('================')
    logger.error("An error occurred: ", exc_info=True)
    logger.info('================')
    logger.error(e)
    logger.info('================')
    logger.error(sys.exc_info())
    logger.info('================e')
    raise e

        
file 文件中
2024-06-28 19:18:36 - __main__ - ERROR - 错误：出了些问题，状态：500，更多信息：额外信息
2024-06-28 19:18:36 - __main__ - INFO - ================
2024-06-28 19:18:36 - __main__ - ERROR - An error occurred: 
Traceback (most recent call last):
  File "/Users/wanglongxin/Desktop/language/python-up/python_base/exceptionMy/execLog.py", line 60, in <module>
    raise MyException("出了些问题", 500, "额外信息")
MyException: 错误：出了些问题，状态：500，更多信息：额外信息
2024-06-28 19:18:36 - __main__ - INFO - ================
2024-06-28 19:18:36 - __main__ - ERROR - 错误：出了些问题，状态：500，更多信息：额外信息
2024-06-28 19:18:36 - __main__ - INFO - ================
2024-06-28 19:18:36 - __main__ - ERROR - (<class '__main__.MyException'>, MyException('出了些问题'), <traceback object at 0x100f8b300>)
2024-06-28 19:18:36 - __main__ - INFO - ================e
```
